# 9. Manejo de Errores y Excepciones en Go

## 9.1. Manejo de Errores con if err != nil

En Go, el manejo de errores se realiza utilizando la construcción `if err != nil`, en lugar de usar bloques try-catch como en otros lenguajes. Go fomenta el manejo explícito de errores, verificándolos inmediatamente después de realizar operaciones que puedan fallar.

```go
if err != nil {
    // Manejo del error
    log.Fatal(err)
}

```

- ### Patrón Común de Manejo de Errores

  - Retorna múltiples valores, uno de los cuales es de tipo error.
  - El valor de error se compara con `nil` para verificar si ocurrió un error.

    ```go
    package main

    import (
        "errors"
        "fmt"
    )

    func divide(a, b int) (int, error) {
        if b == 0 {
            return 0, errors.New("división por cero")
        }
        return a / b, nil
    }

    func main() {
        result, err := divide(4, 0)
        if err != nil {
            fmt.Println("Error:", err)
        } else {
            fmt.Println("Resultado:", result)
        }
    }

    ```

---

## 9.2. Lanzar Errores con panic

Aunque Go no cuenta con un comando throw como en otros lenguajes, se puede usar `panic` para lanzar errores graves. El uso de `panic` está reservado para situaciones excepcionales y normalmente se evita su uso en errores controlables.

```go
func checkPositive(value int) {
    if value < 0 {
        panic("el valor no puede ser negativo")
    }
}

```

### Uso de panic

- Detiene la ejecución normal del programa.
- Se utiliza cuando no es posible manejar el error localmente.

  ```go
  func main() {
      checkPositive(-1)
      fmt.Println("Esto no se ejecutará.")
  }

  ```

---

## 9.3. Uso de defer como finally

Go no tiene un bloque finally, pero se puede replicar su comportamiento con `defer`, que asegura que un bloque de código se ejecute al final de la ejecución de la función, independientemente de si ocurrió un error o no.

```go
func readFile() {
    file, err := os.Open("file.txt")
    if err != nil {
        log.Fatal(err)
    }
    defer file.Close() // Se asegura que se cierre el archivo
    // Leer el archivo
}

```

- **Comportamiento de defer**

  - Los bloques de código defer se ejecutan en orden inverso.
  - Asegura la liberación de recursos como archivos o conexiones de red.

---

## 9.4. Errores en Tiempo de Compilación vs. Tiempo de Ejecución

- ### Errores en Tiempo de Compilación

  Son aquellos detectados por el compilador antes de ejecutar el programa, como errores de sintaxis, tipos incompatibles o referencias a variables no definidas.

  - **Ejemplo de error de compilación:**

    ```go
    var x int = "texto"  // Error, tipo incorrecto

    ```

- ### Errores en Tiempo de Ejecución

  Ocurren mientras el programa está en ejecución, como la división por cero o el acceso a un valor nulo.

  - **Ejemplo de error en tiempo de ejecución:**

    ```go
    func divide(a, b int) int {
        return a / b // Causará pánico si b es 0
    }

    ```

---

## 9.5. Validación de Entrada para Prevenir Errores

La validación de entrada es crucial para prevenir errores en tiempo de ejecución. Go permite realizar validaciones explícitas antes de realizar operaciones.

```go
func validateAge(age int) error {
    if age < 0 {
        return fmt.Errorf("la edad no puede ser negativa")
    }
    return nil
}

func main() {
    err := validateAge(-5)
    if err != nil {
        fmt.Println("Error:", err)
    }
}

```

---

## 9.6. Uso de os.Exit para Código de Salida

El código de salida en Go se puede controlar utilizando la función `os.Exit()`. Esto permite definir si la ejecución del programa fue exitosa o si hubo un error.

- **Código de Salida 0:** Indica una ejecución exitosa.
- **Códigos diferentes de 0:** Indican algún tipo de error.

```go
package main

import (
    "fmt"
    "os"
)

func main() {
    if err := runApp(); err != nil {
        fmt.Println("Error:", err)
        os.Exit(1) // Error, salida con código 1
    }
    os.Exit(0) // Salida exitosa
}

func runApp() error {
    // Lógica de la aplicación
    return nil
}

```

---

## 9.7. Manejo de Pánico y Recuperación (panic y recover)

`recover()` es una función que se utiliza para recuperar un programa de un estado de pánico, permitiendo que la ejecución continúe de forma controlada.

```go
package main

import "fmt"

func divide(a, b int) int {
    defer func() {
        if r := recover(); r != nil {
            fmt.Println("Recuperado del pánico:", r)
        }
    }()

    if b == 0 {
        panic("división por cero")
    }

    return a / b
}

func main() {
    fmt.Println(divide(4, 2))
    fmt.Println(divide(4, 0)) // Se recuperará del pánico
    fmt.Println("Programa continúa después del pánico.")
}

```

---

## 9.8. Error Wrapping y Unwrapping en Go

Go permite "envolver" (wrap) errores utilizando el paquete estándar `fmt` o el paquete errors. Esto es útil para agregar contexto adicional a un error sin perder el error original.

### Wrapping de Errores

Puedes envolver errores usando `fmt.Errorf()` con el formato `%w`, que permite envolver un error existente con un nuevo mensaje contextual.

```go
package main

import (
    "fmt"
    "errors"
)

func readFile() error {
    err := errors.New("archivo no encontrado")
    return fmt.Errorf("error leyendo archivo: %w", err) // Wrap del error original
}

func main() {
    err := readFile()
    if err != nil {
        fmt.Println("Error:", err)
    }
}

```

### Unwrapping de Errores

Para "desenvolver" (unwrap) un error envuelto y acceder al error original, puedes usar `errors.Unwrap()` o las funciones `errors.Is()` y `errors.As()` para comparar y trabajar con errores envueltos.

- **`errors.Unwrap`:** Recupera el error original envuelto.

  ```go
  package main

  import (
      "fmt"
      "errors"
  )

  func main() {
      originalErr := errors.New("error original")
      wrappedErr := fmt.Errorf("envolviendo el error: %w", originalErr)

      fmt.Println(wrappedErr)                  // Muestra el error envuelto
      fmt.Println(errors.Unwrap(wrappedErr))   // Muestra el error original
  }

  ```

- **`errors.Is`:** Compara el error envuelto con un error específico, útil para manejar errores específicos de manera más detallada.

  ```go
  package main

  import (
      "fmt"
      "errors"
  )

  var ErrNotFound = errors.New("archivo no encontrado")

  func readFile() error {
      return fmt.Errorf("error leyendo archivo: %w", ErrNotFound)
  }

  func main() {
      err := readFile()

      if errors.Is(err, ErrNotFound) {
          fmt.Println("Error: el archivo no fue encontrado.")
      } else {
          fmt.Println("Otro error:", err)
      }
  }

  ```

- **`errors.As`:** Convierte el error envuelto en un tipo de error específico, permitiendo un manejo más detallado de errores personalizados.

  ```go
  package main

  import (
      "fmt"
      "errors"
  )

  type MyCustomError struct {
      Message string
  }

  func (e *MyCustomError) Error() string {
      return e.Message
  }

  func returnError() error {
      return fmt.Errorf("error: %w", &MyCustomError{"Error personalizado"})
  }

  func main() {
      err := returnError()

      var customErr *MyCustomError
      if errors.As(err, &customErr) {
          fmt.Println("Error personalizado detectado:", customErr.Message)
      } else {
          fmt.Println("Error general:", err)
      }
  }

  ```
